Server closed the connection: 0 bytes read on a total of 8 expected bytes
Server resent the older message 7405999571853063169, ignoring
Cannot get difference since the account is likely misusing the session: database is locked
Task exception was never retrieved
future: <Task finished name='Task-58' coro=<TelegramBaseClient._disconnect_coro() done, defined at /usr/local/lib/python3.10/dist-packages/telethon/client/telegrambaseclient.py:705> exception=OperationalError('database is locked')>
Traceback (most recent call last):
  File "/usr/local/lib/python3.10/dist-packages/telethon/client/telegrambaseclient.py", line 735, in _disconnect_coro
    self._save_states_and_entities()
  File "/usr/local/lib/python3.10/dist-packages/telethon/client/telegrambaseclient.py", line 692, in _save_states_and_entities
    self.session.process_entities(types.contacts.ResolvedPeer(None, [e._as_input_peer() for e in entities], []))
  File "/usr/local/lib/python3.10/dist-packages/telethon/sessions/sqlite.py", line 301, in process_entities
    c.executemany(
sqlite3.OperationalError: database is locked
Traceback (most recent call last):
  File "/usr/local/lib/python3.10/dist-packages/telethon/client/updates.py", line 38, in _run_until_disconnected
    raise self._updates_error
  File "/usr/local/lib/python3.10/dist-packages/telethon/client/updates.py", line 308, in _update_loop
    diff = await self(get_diff)
  File "/usr/local/lib/python3.10/dist-packages/telethon/client/users.py", line 30, in __call__
    return await self._call(self._sender, request, ordered=ordered)
  File "/usr/local/lib/python3.10/dist-packages/telethon/client/users.py", line 88, in _call
    self.session.process_entities(result)
  File "/usr/local/lib/python3.10/dist-packages/telethon/sessions/sqlite.py", line 301, in process_entities
    c.executemany(
sqlite3.OperationalError: database is locked

During handling of the above exception, another exception occurred:

Traceback (most recent call last):
  File "/usr/local/lib/python3.10/dist-packages/telethon/client/updates.py", line 96, in run_until_disconnected
    return self.loop.run_until_complete(self._run_until_disconnected())
  File "/usr/lib/python3.10/asyncio/base_events.py", line 649, in run_until_complete
    return future.result()
  File "/usr/local/lib/python3.10/dist-packages/telethon/client/updates.py", line 43, in _run_until_disconnected
    await self.disconnect()
  File "/usr/local/lib/python3.10/dist-packages/telethon/client/telegrambaseclient.py", line 735, in _disconnect_coro
    self._save_states_and_entities()
  File "/usr/local/lib/python3.10/dist-packages/telethon/client/telegrambaseclient.py", line 692, in _save_states_and_entities
    self.session.process_entities(types.contacts.ResolvedPeer(None, [e._as_input_peer() for e in entities], []))
  File "/usr/local/lib/python3.10/dist-packages/telethon/sessions/sqlite.py", line 301, in process_entities
    c.executemany(
sqlite3.OperationalError: database is locked

During handling of the above exception, another exception occurred:

Traceback (most recent call last):
  File "/root/bot/bot.py", line 113, in <module>
    client.run_until_disconnected()
  File "/usr/local/lib/python3.10/dist-packages/telethon/client/updates.py", line 101, in run_until_disconnected
    self.disconnect()
  File "/usr/local/lib/python3.10/dist-packages/telethon/client/telegrambaseclient.py", line 649, in disconnect
    self.loop.run_until_complete(self._disconnect_coro())
  File "/usr/lib/python3.10/asyncio/base_events.py", line 649, in run_until_complete
    return future.result()
  File "/usr/local/lib/python3.10/dist-packages/telethon/client/telegrambaseclient.py", line 735, in _disconnect_coro
    self._save_states_and_entities()
  File "/usr/local/lib/python3.10/dist-packages/telethon/client/telegrambaseclient.py", line 692, in _save_states_and_entities
    self.session.process_entities(types.contacts.ResolvedPeer(None, [e._as_input_peer() for e in entities], []))
  File "/usr/local/lib/python3.10/dist-packages/telethon/sessions/sqlite.py", line 301, in process_entities
    c.executemany(
sqlite3.OperationalError: database is locked
Attempt 1 at connecting failed: TimeoutError: 
Attempt 2 at connecting failed: TimeoutError: 
Server closed the connection: [Errno 104] Connection reset by peer
Traceback (most recent call last):
  File "/root/bot/bot.py", line 12, in <module>
    client = TelegramClient('TagAllBot', API_ID, API_HASH).start(bot_token=BOT_TOKEN)
  File "/usr/local/lib/python3.10/dist-packages/telethon/client/auth.py", line 128, in start
    else self.loop.run_until_complete(coro)
  File "/usr/lib/python3.10/asyncio/base_events.py", line 649, in run_until_complete
    return future.result()
  File "/usr/local/lib/python3.10/dist-packages/telethon/client/auth.py", line 135, in _start
    await self.connect()
  File "/usr/local/lib/python3.10/dist-packages/telethon/client/telegrambaseclient.py", line 558, in connect
    self.session.auth_key = self._sender.auth_key
  File "/usr/local/lib/python3.10/dist-packages/telethon/sessions/sqlite.py", line 180, in auth_key
    self._update_session_table()
  File "/usr/local/lib/python3.10/dist-packages/telethon/sessions/sqlite.py", line 194, in _update_session_table
    c.execute('delete from sessions')
sqlite3.OperationalError: database is locked
Task was destroyed but it is pending!
task: <Task pending name='Task-5' coro=<MTProtoSender._send_loop() running at /usr/local/lib/python3.10/dist-packages/telethon/network/mtprotosender.py:464> wait_for=<Future pending cb=[Task.task_wakeup()]>>
Task was destroyed but it is pending!
task: <Task pending name='Task-6' coro=<MTProtoSender._recv_loop() running at /usr/local/lib/python3.10/dist-packages/telethon/network/mtprotosender.py:507> wait_for=<Future pending cb=[Task.task_wakeup()]>>
Task was destroyed but it is pending!
task: <Task pending name='Task-3' coro=<Connection._send_loop() running at /usr/local/lib/python3.10/dist-packages/telethon/network/connection/connection.py:316> wait_for=<Future pending cb=[Task.task_wakeup()]>>
Task was destroyed but it is pending!
task: <Task pending name='Task-4' coro=<Connection._recv_loop() running at /usr/local/lib/python3.10/dist-packages/telethon/network/connection/connection.py:335> wait_for=<Future pending cb=[Task.task_wakeup()]>>
Exception ignored in: <coroutine object Connection._recv_loop at 0x7f30fae869d0>
RuntimeError: coroutine ignored GeneratorExit
Task exception was never retrieved
future: <Task finished name='Task-10' coro=<send_random_message() done, defined at /root/bot/bot.py:32> exception=NameError("name 'asyncio' is not defined")>
Traceback (most recent call last):
  File "/root/bot/bot.py", line 37, in send_random_message
    await asyncio.sleep(random.randint(5, 15))  # случайный интервал между 5 и 15 секундами
NameError: name 'asyncio' is not defined
Task exception was never retrieved
future: <Task finished name='Task-10' coro=<send_random_message() done, defined at /root/bot/bot.py:32> exception=NameError("name 'asyncio' is not defined")>
Traceback (most recent call last):
  File "/root/bot/bot.py", line 37, in send_random_message
    await asyncio.sleep(random.randint(5, 15))  # случайный интервал между 5 и 15 секундами
NameError: name 'asyncio' is not defined
Traceback (most recent call last):
  File "/root/bot/bot.py", line 147, in <module>
    client.loop.create_task(send_random_message('-1001909447595'))
NameError: name 'send_random_message' is not defined. Did you mean: 'generate_random_message'?
Traceback (most recent call last):
  File "/root/bot/bot.py", line 147, in <module>
    client.loop.create_task(send_random_message('-1001909447595'))
NameError: name 'send_random_message' is not defined. Did you mean: 'generate_random_message'?
Traceback (most recent call last):
  File "/root/bot/bot.py", line 147, in <module>
    client.loop.create_task(send_random_message('-1001909447595'))
NameError: name 'send_random_message' is not defined. Did you mean: 'generate_random_message'?
Unhandled exception on store_message
Traceback (most recent call last):
  File "/usr/local/lib/python3.10/dist-packages/telethon/client/updates.py", line 570, in _dispatch_update
    await callback(event)
  File "/root/bot/bot.py", line 43, in store_message
    await client.send_message(event.chat_id, message)  # Отправляем сообщение в беседу
  File "/usr/local/lib/python3.10/dist-packages/telethon/client/messages.py", line 905, in send_message
    result = await self(request)
  File "/usr/local/lib/python3.10/dist-packages/telethon/client/users.py", line 30, in __call__
    return await self._call(self._sender, request, ordered=ordered)
  File "/usr/local/lib/python3.10/dist-packages/telethon/client/users.py", line 133, in _call
    raise ValueError('Request was unsuccessful {} time(s)'
ValueError: Request was unsuccessful 6 time(s)
Unhandled exception on store_message
Traceback (most recent call last):
  File "/usr/local/lib/python3.10/dist-packages/telethon/client/updates.py", line 570, in _dispatch_update
    await callback(event)
  File "/root/bot/bot.py", line 43, in store_message
    await client.send_message(event.chat_id, message)  # Отправляем сообщение в беседу
  File "/usr/local/lib/python3.10/dist-packages/telethon/client/messages.py", line 905, in send_message
    result = await self(request)
  File "/usr/local/lib/python3.10/dist-packages/telethon/client/users.py", line 30, in __call__
    return await self._call(self._sender, request, ordered=ordered)
  File "/usr/local/lib/python3.10/dist-packages/telethon/client/users.py", line 133, in _call
    raise ValueError('Request was unsuccessful {} time(s)'
ValueError: Request was unsuccessful 6 time(s)
Unhandled exception on store_message
Traceback (most recent call last):
  File "/usr/local/lib/python3.10/dist-packages/telethon/client/updates.py", line 570, in _dispatch_update
    await callback(event)
  File "/root/bot/bot.py", line 43, in store_message
    await client.send_message(event.chat_id, message)  # Отправляем сообщение в беседу
  File "/usr/local/lib/python3.10/dist-packages/telethon/client/messages.py", line 905, in send_message
    result = await self(request)
  File "/usr/local/lib/python3.10/dist-packages/telethon/client/users.py", line 30, in __call__
    return await self._call(self._sender, request, ordered=ordered)
  File "/usr/local/lib/python3.10/dist-packages/telethon/client/users.py", line 133, in _call
    raise ValueError('Request was unsuccessful {} time(s)'
ValueError: Request was unsuccessful 6 time(s)
Unhandled exception on store_message
Traceback (most recent call last):
  File "/usr/local/lib/python3.10/dist-packages/telethon/client/updates.py", line 570, in _dispatch_update
    await callback(event)
  File "/root/bot/bot.py", line 43, in store_message
    await client.send_message(event.chat_id, message)  # Отправляем сообщение в беседу
  File "/usr/local/lib/python3.10/dist-packages/telethon/client/messages.py", line 905, in send_message
    result = await self(request)
  File "/usr/local/lib/python3.10/dist-packages/telethon/client/users.py", line 30, in __call__
    return await self._call(self._sender, request, ordered=ordered)
  File "/usr/local/lib/python3.10/dist-packages/telethon/client/users.py", line 133, in _call
    raise ValueError('Request was unsuccessful {} time(s)'
ValueError: Request was unsuccessful 6 time(s)
Unhandled exception on store_message
Traceback (most recent call last):
  File "/usr/local/lib/python3.10/dist-packages/telethon/client/updates.py", line 570, in _dispatch_update
    await callback(event)
  File "/root/bot/bot.py", line 43, in store_message
    await client.send_message(event.chat_id, message)  # Отправляем сообщение в беседу
  File "/usr/local/lib/python3.10/dist-packages/telethon/client/messages.py", line 905, in send_message
    result = await self(request)
  File "/usr/local/lib/python3.10/dist-packages/telethon/client/users.py", line 30, in __call__
    return await self._call(self._sender, request, ordered=ordered)
  File "/usr/local/lib/python3.10/dist-packages/telethon/client/users.py", line 133, in _call
    raise ValueError('Request was unsuccessful {} time(s)'
ValueError: Request was unsuccessful 6 time(s)
Unhandled exception on store_message
Traceback (most recent call last):
  File "/usr/local/lib/python3.10/dist-packages/telethon/client/updates.py", line 570, in _dispatch_update
    await callback(event)
  File "/root/bot/bot.py", line 43, in store_message
    await client.send_message(event.chat_id, message)  # Отправляем сообщение в беседу
  File "/usr/local/lib/python3.10/dist-packages/telethon/client/messages.py", line 905, in send_message
    result = await self(request)
  File "/usr/local/lib/python3.10/dist-packages/telethon/client/users.py", line 30, in __call__
    return await self._call(self._sender, request, ordered=ordered)
  File "/usr/local/lib/python3.10/dist-packages/telethon/client/users.py", line 133, in _call
    raise ValueError('Request was unsuccessful {} time(s)'
ValueError: Request was unsuccessful 6 time(s)
Unhandled exception on store_message
Traceback (most recent call last):
  File "/usr/local/lib/python3.10/dist-packages/telethon/client/updates.py", line 570, in _dispatch_update
    await callback(event)
  File "/root/bot/bot.py", line 43, in store_message
    await client.send_message(event.chat_id, message)  # Отправляем сообщение в беседу
  File "/usr/local/lib/python3.10/dist-packages/telethon/client/messages.py", line 905, in send_message
    result = await self(request)
  File "/usr/local/lib/python3.10/dist-packages/telethon/client/users.py", line 30, in __call__
    return await self._call(self._sender, request, ordered=ordered)
  File "/usr/local/lib/python3.10/dist-packages/telethon/client/users.py", line 133, in _call
    raise ValueError('Request was unsuccessful {} time(s)'
ValueError: Request was unsuccessful 6 time(s)
Unhandled exception on store_message
Traceback (most recent call last):
  File "/usr/local/lib/python3.10/dist-packages/telethon/client/updates.py", line 570, in _dispatch_update
    await callback(event)
  File "/root/bot/bot.py", line 43, in store_message
    await client.send_message(event.chat_id, message)  # Отправляем сообщение в беседу
  File "/usr/local/lib/python3.10/dist-packages/telethon/client/messages.py", line 905, in send_message
    result = await self(request)
  File "/usr/local/lib/python3.10/dist-packages/telethon/client/users.py", line 30, in __call__
    return await self._call(self._sender, request, ordered=ordered)
  File "/usr/local/lib/python3.10/dist-packages/telethon/client/users.py", line 133, in _call
    raise ValueError('Request was unsuccessful {} time(s)'
ValueError: Request was unsuccessful 6 time(s)
Unhandled exception on store_message
Traceback (most recent call last):
  File "/usr/local/lib/python3.10/dist-packages/telethon/client/updates.py", line 570, in _dispatch_update
    await callback(event)
  File "/root/bot/bot.py", line 43, in store_message
    await client.send_message(event.chat_id, message)  # Отправляем сообщение в беседу
  File "/usr/local/lib/python3.10/dist-packages/telethon/client/messages.py", line 905, in send_message
    result = await self(request)
  File "/usr/local/lib/python3.10/dist-packages/telethon/client/users.py", line 30, in __call__
    return await self._call(self._sender, request, ordered=ordered)
  File "/usr/local/lib/python3.10/dist-packages/telethon/client/users.py", line 133, in _call
    raise ValueError('Request was unsuccessful {} time(s)'
ValueError: Request was unsuccessful 6 time(s)
Unhandled exception on store_message
Traceback (most recent call last):
  File "/usr/local/lib/python3.10/dist-packages/telethon/client/updates.py", line 570, in _dispatch_update
    await callback(event)
  File "/root/bot/bot.py", line 43, in store_message
    await client.send_message(event.chat_id, message)  # Отправляем сообщение в беседу
  File "/usr/local/lib/python3.10/dist-packages/telethon/client/messages.py", line 905, in send_message
    result = await self(request)
  File "/usr/local/lib/python3.10/dist-packages/telethon/client/users.py", line 30, in __call__
    return await self._call(self._sender, request, ordered=ordered)
  File "/usr/local/lib/python3.10/dist-packages/telethon/client/users.py", line 133, in _call
    raise ValueError('Request was unsuccessful {} time(s)'
ValueError: Request was unsuccessful 6 time(s)
Unhandled exception on store_message
Traceback (most recent call last):
  File "/usr/local/lib/python3.10/dist-packages/telethon/client/updates.py", line 570, in _dispatch_update
    await callback(event)
  File "/root/bot/bot.py", line 43, in store_message
    await client.send_message(event.chat_id, message)  # Отправляем сообщение в беседу
  File "/usr/local/lib/python3.10/dist-packages/telethon/client/messages.py", line 905, in send_message
    result = await self(request)
  File "/usr/local/lib/python3.10/dist-packages/telethon/client/users.py", line 30, in __call__
    return await self._call(self._sender, request, ordered=ordered)
  File "/usr/local/lib/python3.10/dist-packages/telethon/client/users.py", line 133, in _call
    raise ValueError('Request was unsuccessful {} time(s)'
ValueError: Request was unsuccessful 6 time(s)
Unhandled exception on store_message
Traceback (most recent call last):
  File "/usr/local/lib/python3.10/dist-packages/telethon/client/updates.py", line 570, in _dispatch_update
    await callback(event)
  File "/root/bot/bot.py", line 43, in store_message
    await client.send_message(event.chat_id, message)  # Отправляем сообщение в беседу
  File "/usr/local/lib/python3.10/dist-packages/telethon/client/messages.py", line 905, in send_message
    result = await self(request)
  File "/usr/local/lib/python3.10/dist-packages/telethon/client/users.py", line 30, in __call__
    return await self._call(self._sender, request, ordered=ordered)
  File "/usr/local/lib/python3.10/dist-packages/telethon/client/users.py", line 133, in _call
    raise ValueError('Request was unsuccessful {} time(s)'
ValueError: Request was unsuccessful 6 time(s)
Unhandled exception on store_message
Traceback (most recent call last):
  File "/usr/local/lib/python3.10/dist-packages/telethon/client/updates.py", line 570, in _dispatch_update
    await callback(event)
  File "/root/bot/bot.py", line 43, in store_message
    await client.send_message(event.chat_id, message)  # Отправляем сообщение в беседу
  File "/usr/local/lib/python3.10/dist-packages/telethon/client/messages.py", line 905, in send_message
    result = await self(request)
  File "/usr/local/lib/python3.10/dist-packages/telethon/client/users.py", line 30, in __call__
    return await self._call(self._sender, request, ordered=ordered)
  File "/usr/local/lib/python3.10/dist-packages/telethon/client/users.py", line 133, in _call
    raise ValueError('Request was unsuccessful {} time(s)'
ValueError: Request was unsuccessful 6 time(s)
Unhandled exception on store_message
Traceback (most recent call last):
  File "/usr/local/lib/python3.10/dist-packages/telethon/client/updates.py", line 570, in _dispatch_update
    await callback(event)
  File "/root/bot/bot.py", line 43, in store_message
    await client.send_message(event.chat_id, message)  # Отправляем сообщение в беседу
  File "/usr/local/lib/python3.10/dist-packages/telethon/client/messages.py", line 905, in send_message
    result = await self(request)
  File "/usr/local/lib/python3.10/dist-packages/telethon/client/users.py", line 30, in __call__
    return await self._call(self._sender, request, ordered=ordered)
  File "/usr/local/lib/python3.10/dist-packages/telethon/client/users.py", line 133, in _call
    raise ValueError('Request was unsuccessful {} time(s)'
ValueError: Request was unsuccessful 6 time(s)
Unhandled exception on store_message
Traceback (most recent call last):
  File "/usr/local/lib/python3.10/dist-packages/telethon/client/updates.py", line 570, in _dispatch_update
    await callback(event)
  File "/root/bot/bot.py", line 43, in store_message
    await client.send_message(event.chat_id, message)  # Отправляем сообщение в беседу
  File "/usr/local/lib/python3.10/dist-packages/telethon/client/messages.py", line 905, in send_message
    result = await self(request)
  File "/usr/local/lib/python3.10/dist-packages/telethon/client/users.py", line 30, in __call__
    return await self._call(self._sender, request, ordered=ordered)
  File "/usr/local/lib/python3.10/dist-packages/telethon/client/users.py", line 133, in _call
    raise ValueError('Request was unsuccessful {} time(s)'
ValueError: Request was unsuccessful 6 time(s)
Unhandled exception on store_message
Traceback (most recent call last):
  File "/usr/local/lib/python3.10/dist-packages/telethon/client/updates.py", line 570, in _dispatch_update
    await callback(event)
  File "/root/bot/bot.py", line 43, in store_message
    await client.send_message(event.chat_id, message)  # Отправляем сообщение в беседу
  File "/usr/local/lib/python3.10/dist-packages/telethon/client/messages.py", line 905, in send_message
    result = await self(request)
  File "/usr/local/lib/python3.10/dist-packages/telethon/client/users.py", line 30, in __call__
    return await self._call(self._sender, request, ordered=ordered)
  File "/usr/local/lib/python3.10/dist-packages/telethon/client/users.py", line 133, in _call
    raise ValueError('Request was unsuccessful {} time(s)'
ValueError: Request was unsuccessful 6 time(s)
Unhandled exception on store_message
Traceback (most recent call last):
  File "/usr/local/lib/python3.10/dist-packages/telethon/client/updates.py", line 570, in _dispatch_update
    await callback(event)
  File "/root/bot/bot.py", line 43, in store_message
    await client.send_message(event.chat_id, message)  # Отправляем сообщение в беседу
  File "/usr/local/lib/python3.10/dist-packages/telethon/client/messages.py", line 905, in send_message
    result = await self(request)
  File "/usr/local/lib/python3.10/dist-packages/telethon/client/users.py", line 30, in __call__
    return await self._call(self._sender, request, ordered=ordered)
  File "/usr/local/lib/python3.10/dist-packages/telethon/client/users.py", line 133, in _call
    raise ValueError('Request was unsuccessful {} time(s)'
ValueError: Request was unsuccessful 6 time(s)
Unhandled exception on store_message
Traceback (most recent call last):
  File "/usr/local/lib/python3.10/dist-packages/telethon/client/updates.py", line 570, in _dispatch_update
    await callback(event)
  File "/root/bot/bot.py", line 43, in store_message
    await client.send_message(event.chat_id, message)  # Отправляем сообщение в беседу
  File "/usr/local/lib/python3.10/dist-packages/telethon/client/messages.py", line 905, in send_message
    result = await self(request)
  File "/usr/local/lib/python3.10/dist-packages/telethon/client/users.py", line 30, in __call__
    return await self._call(self._sender, request, ordered=ordered)
  File "/usr/local/lib/python3.10/dist-packages/telethon/client/users.py", line 133, in _call
    raise ValueError('Request was unsuccessful {} time(s)'
ValueError: Request was unsuccessful 6 time(s)
Unhandled exception on store_message
Traceback (most recent call last):
  File "/usr/local/lib/python3.10/dist-packages/telethon/client/updates.py", line 570, in _dispatch_update
    await callback(event)
  File "/root/bot/bot.py", line 43, in store_message
    await client.send_message(event.chat_id, message)  # Отправляем сообщение в беседу
  File "/usr/local/lib/python3.10/dist-packages/telethon/client/messages.py", line 905, in send_message
    result = await self(request)
  File "/usr/local/lib/python3.10/dist-packages/telethon/client/users.py", line 30, in __call__
    return await self._call(self._sender, request, ordered=ordered)
  File "/usr/local/lib/python3.10/dist-packages/telethon/client/users.py", line 133, in _call
    raise ValueError('Request was unsuccessful {} time(s)'
ValueError: Request was unsuccessful 6 time(s)
Unhandled exception on store_message
Traceback (most recent call last):
  File "/usr/local/lib/python3.10/dist-packages/telethon/client/updates.py", line 570, in _dispatch_update
    await callback(event)
  File "/root/bot/bot.py", line 43, in store_message
    await client.send_message(event.chat_id, message)  # Отправляем сообщение в беседу
  File "/usr/local/lib/python3.10/dist-packages/telethon/client/messages.py", line 905, in send_message
    result = await self(request)
  File "/usr/local/lib/python3.10/dist-packages/telethon/client/users.py", line 30, in __call__
    return await self._call(self._sender, request, ordered=ordered)
  File "/usr/local/lib/python3.10/dist-packages/telethon/client/users.py", line 133, in _call
    raise ValueError('Request was unsuccessful {} time(s)'
ValueError: Request was unsuccessful 6 time(s)
Unhandled exception on store_message
Traceback (most recent call last):
  File "/usr/local/lib/python3.10/dist-packages/telethon/client/updates.py", line 570, in _dispatch_update
    await callback(event)
  File "/root/bot/bot.py", line 43, in store_message
    await client.send_message(event.chat_id, message)  # Отправляем сообщение в беседу
  File "/usr/local/lib/python3.10/dist-packages/telethon/client/messages.py", line 905, in send_message
    result = await self(request)
  File "/usr/local/lib/python3.10/dist-packages/telethon/client/users.py", line 30, in __call__
    return await self._call(self._sender, request, ordered=ordered)
  File "/usr/local/lib/python3.10/dist-packages/telethon/client/users.py", line 133, in _call
    raise ValueError('Request was unsuccessful {} time(s)'
ValueError: Request was unsuccessful 6 time(s)
Unhandled exception on store_message
Traceback (most recent call last):
  File "/usr/local/lib/python3.10/dist-packages/telethon/client/updates.py", line 570, in _dispatch_update
    await callback(event)
  File "/root/bot/bot.py", line 43, in store_message
    await client.send_message(event.chat_id, message)  # Отправляем сообщение в беседу
  File "/usr/local/lib/python3.10/dist-packages/telethon/client/messages.py", line 905, in send_message
    result = await self(request)
  File "/usr/local/lib/python3.10/dist-packages/telethon/client/users.py", line 30, in __call__
    return await self._call(self._sender, request, ordered=ordered)
  File "/usr/local/lib/python3.10/dist-packages/telethon/client/users.py", line 133, in _call
    raise ValueError('Request was unsuccessful {} time(s)'
ValueError: Request was unsuccessful 6 time(s)
Unhandled exception on store_message
Traceback (most recent call last):
  File "/usr/local/lib/python3.10/dist-packages/telethon/client/updates.py", line 570, in _dispatch_update
    await callback(event)
  File "/root/bot/bot.py", line 43, in store_message
    await client.send_message(event.chat_id, message)  # Отправляем сообщение в беседу
  File "/usr/local/lib/python3.10/dist-packages/telethon/client/messages.py", line 905, in send_message
    result = await self(request)
  File "/usr/local/lib/python3.10/dist-packages/telethon/client/users.py", line 30, in __call__
    return await self._call(self._sender, request, ordered=ordered)
  File "/usr/local/lib/python3.10/dist-packages/telethon/client/users.py", line 133, in _call
    raise ValueError('Request was unsuccessful {} time(s)'
ValueError: Request was unsuccessful 6 time(s)
Unhandled exception on store_message
Traceback (most recent call last):
  File "/usr/local/lib/python3.10/dist-packages/telethon/client/updates.py", line 570, in _dispatch_update
    await callback(event)
  File "/root/bot/bot.py", line 43, in store_message
    await client.send_message(event.chat_id, message)  # Отправляем сообщение в беседу
  File "/usr/local/lib/python3.10/dist-packages/telethon/client/messages.py", line 905, in send_message
    result = await self(request)
  File "/usr/local/lib/python3.10/dist-packages/telethon/client/users.py", line 30, in __call__
    return await self._call(self._sender, request, ordered=ordered)
  File "/usr/local/lib/python3.10/dist-packages/telethon/client/users.py", line 133, in _call
    raise ValueError('Request was unsuccessful {} time(s)'
ValueError: Request was unsuccessful 6 time(s)
Unhandled exception on store_message
Traceback (most recent call last):
  File "/usr/local/lib/python3.10/dist-packages/telethon/client/updates.py", line 570, in _dispatch_update
    await callback(event)
  File "/root/bot/bot.py", line 43, in store_message
    await client.send_message(event.chat_id, message)  # Отправляем сообщение в беседу
  File "/usr/local/lib/python3.10/dist-packages/telethon/client/messages.py", line 905, in send_message
    result = await self(request)
  File "/usr/local/lib/python3.10/dist-packages/telethon/client/users.py", line 30, in __call__
    return await self._call(self._sender, request, ordered=ordered)
  File "/usr/local/lib/python3.10/dist-packages/telethon/client/users.py", line 133, in _call
    raise ValueError('Request was unsuccessful {} time(s)'
ValueError: Request was unsuccessful 6 time(s)
Unhandled exception on store_message
Traceback (most recent call last):
  File "/usr/local/lib/python3.10/dist-packages/telethon/client/updates.py", line 570, in _dispatch_update
    await callback(event)
  File "/root/bot/bot.py", line 43, in store_message
    await client.send_message(event.chat_id, message)  # Отправляем сообщение в беседу
  File "/usr/local/lib/python3.10/dist-packages/telethon/client/messages.py", line 905, in send_message
    result = await self(request)
  File "/usr/local/lib/python3.10/dist-packages/telethon/client/users.py", line 30, in __call__
    return await self._call(self._sender, request, ordered=ordered)
  File "/usr/local/lib/python3.10/dist-packages/telethon/client/users.py", line 133, in _call
    raise ValueError('Request was unsuccessful {} time(s)'
ValueError: Request was unsuccessful 6 time(s)
Unhandled exception on store_message
Traceback (most recent call last):
  File "/usr/local/lib/python3.10/dist-packages/telethon/client/updates.py", line 570, in _dispatch_update
    await callback(event)
  File "/root/bot/bot.py", line 43, in store_message
    await client.send_message(event.chat_id, message)  # Отправляем сообщение в беседу
  File "/usr/local/lib/python3.10/dist-packages/telethon/client/messages.py", line 905, in send_message
    result = await self(request)
  File "/usr/local/lib/python3.10/dist-packages/telethon/client/users.py", line 30, in __call__
    return await self._call(self._sender, request, ordered=ordered)
  File "/usr/local/lib/python3.10/dist-packages/telethon/client/users.py", line 133, in _call
    raise ValueError('Request was unsuccessful {} time(s)'
ValueError: Request was unsuccessful 6 time(s)
Unhandled exception on store_message
Traceback (most recent call last):
  File "/usr/local/lib/python3.10/dist-packages/telethon/client/updates.py", line 570, in _dispatch_update
    await callback(event)
  File "/root/bot/bot.py", line 43, in store_message
    await client.send_message(event.chat_id, message)  # Отправляем сообщение в беседу
  File "/usr/local/lib/python3.10/dist-packages/telethon/client/messages.py", line 905, in send_message
    result = await self(request)
  File "/usr/local/lib/python3.10/dist-packages/telethon/client/users.py", line 30, in __call__
    return await self._call(self._sender, request, ordered=ordered)
  File "/usr/local/lib/python3.10/dist-packages/telethon/client/users.py", line 133, in _call
    raise ValueError('Request was unsuccessful {} time(s)'
ValueError: Request was unsuccessful 6 time(s)
Unhandled exception on store_message
Traceback (most recent call last):
  File "/usr/local/lib/python3.10/dist-packages/telethon/client/updates.py", line 570, in _dispatch_update
    await callback(event)
  File "/root/bot/bot.py", line 43, in store_message
    await client.send_message(event.chat_id, message)  # Отправляем сообщение в беседу
  File "/usr/local/lib/python3.10/dist-packages/telethon/client/messages.py", line 905, in send_message
    result = await self(request)
  File "/usr/local/lib/python3.10/dist-packages/telethon/client/users.py", line 30, in __call__
    return await self._call(self._sender, request, ordered=ordered)
  File "/usr/local/lib/python3.10/dist-packages/telethon/client/users.py", line 133, in _call
    raise ValueError('Request was unsuccessful {} time(s)'
ValueError: Request was unsuccessful 6 time(s)
Unhandled exception on store_message
Traceback (most recent call last):
  File "/usr/local/lib/python3.10/dist-packages/telethon/client/updates.py", line 570, in _dispatch_update
    await callback(event)
  File "/root/bot/bot.py", line 43, in store_message
    await client.send_message(event.chat_id, message)  # Отправляем сообщение в беседу
  File "/usr/local/lib/python3.10/dist-packages/telethon/client/messages.py", line 905, in send_message
    result = await self(request)
  File "/usr/local/lib/python3.10/dist-packages/telethon/client/users.py", line 30, in __call__
    return await self._call(self._sender, request, ordered=ordered)
  File "/usr/local/lib/python3.10/dist-packages/telethon/client/users.py", line 133, in _call
    raise ValueError('Request was unsuccessful {} time(s)'
ValueError: Request was unsuccessful 6 time(s)
Unhandled exception on store_message
Traceback (most recent call last):
  File "/usr/local/lib/python3.10/dist-packages/telethon/client/updates.py", line 570, in _dispatch_update
    await callback(event)
  File "/root/bot/bot.py", line 43, in store_message
    await client.send_message(event.chat_id, message)  # Отправляем сообщение в беседу
  File "/usr/local/lib/python3.10/dist-packages/telethon/client/messages.py", line 905, in send_message
    result = await self(request)
  File "/usr/local/lib/python3.10/dist-packages/telethon/client/users.py", line 30, in __call__
    return await self._call(self._sender, request, ordered=ordered)
  File "/usr/local/lib/python3.10/dist-packages/telethon/client/users.py", line 133, in _call
    raise ValueError('Request was unsuccessful {} time(s)'
ValueError: Request was unsuccessful 6 time(s)
Unhandled exception on store_message
Traceback (most recent call last):
  File "/usr/local/lib/python3.10/dist-packages/telethon/client/updates.py", line 570, in _dispatch_update
    await callback(event)
  File "/root/bot/bot.py", line 43, in store_message
    await client.send_message(event.chat_id, message)  # Отправляем сообщение в беседу
  File "/usr/local/lib/python3.10/dist-packages/telethon/client/messages.py", line 905, in send_message
    result = await self(request)
  File "/usr/local/lib/python3.10/dist-packages/telethon/client/users.py", line 30, in __call__
    return await self._call(self._sender, request, ordered=ordered)
  File "/usr/local/lib/python3.10/dist-packages/telethon/client/users.py", line 133, in _call
    raise ValueError('Request was unsuccessful {} time(s)'
ValueError: Request was unsuccessful 6 time(s)
Unhandled exception on store_message
Traceback (most recent call last):
  File "/usr/local/lib/python3.10/dist-packages/telethon/client/updates.py", line 570, in _dispatch_update
    await callback(event)
  File "/root/bot/bot.py", line 43, in store_message
    await client.send_message(event.chat_id, message)  # Отправляем сообщение в беседу
  File "/usr/local/lib/python3.10/dist-packages/telethon/client/messages.py", line 905, in send_message
    result = await self(request)
  File "/usr/local/lib/python3.10/dist-packages/telethon/client/users.py", line 30, in __call__
    return await self._call(self._sender, request, ordered=ordered)
  File "/usr/local/lib/python3.10/dist-packages/telethon/client/users.py", line 133, in _call
    raise ValueError('Request was unsuccessful {} time(s)'
ValueError: Request was unsuccessful 6 time(s)
Unhandled exception on store_message
Traceback (most recent call last):
  File "/usr/local/lib/python3.10/dist-packages/telethon/client/updates.py", line 570, in _dispatch_update
    await callback(event)
  File "/root/bot/bot.py", line 43, in store_message
    await client.send_message(event.chat_id, message)  # Отправляем сообщение в беседу
  File "/usr/local/lib/python3.10/dist-packages/telethon/client/messages.py", line 905, in send_message
    result = await self(request)
  File "/usr/local/lib/python3.10/dist-packages/telethon/client/users.py", line 30, in __call__
    return await self._call(self._sender, request, ordered=ordered)
  File "/usr/local/lib/python3.10/dist-packages/telethon/client/users.py", line 133, in _call
    raise ValueError('Request was unsuccessful {} time(s)'
ValueError: Request was unsuccessful 6 time(s)
Unhandled exception on store_message
Traceback (most recent call last):
  File "/usr/local/lib/python3.10/dist-packages/telethon/client/updates.py", line 570, in _dispatch_update
    await callback(event)
  File "/root/bot/bot.py", line 43, in store_message
    await client.send_message(event.chat_id, message)  # Отправляем сообщение в беседу
  File "/usr/local/lib/python3.10/dist-packages/telethon/client/messages.py", line 905, in send_message
    result = await self(request)
  File "/usr/local/lib/python3.10/dist-packages/telethon/client/users.py", line 30, in __call__
    return await self._call(self._sender, request, ordered=ordered)
  File "/usr/local/lib/python3.10/dist-packages/telethon/client/users.py", line 133, in _call
    raise ValueError('Request was unsuccessful {} time(s)'
ValueError: Request was unsuccessful 6 time(s)
Unhandled exception on store_message
Traceback (most recent call last):
  File "/usr/local/lib/python3.10/dist-packages/telethon/client/updates.py", line 570, in _dispatch_update
    await callback(event)
  File "/root/bot/bot.py", line 43, in store_message
    await client.send_message(event.chat_id, message)  # Отправляем сообщение в беседу
  File "/usr/local/lib/python3.10/dist-packages/telethon/client/messages.py", line 905, in send_message
    result = await self(request)
  File "/usr/local/lib/python3.10/dist-packages/telethon/client/users.py", line 30, in __call__
    return await self._call(self._sender, request, ordered=ordered)
  File "/usr/local/lib/python3.10/dist-packages/telethon/client/users.py", line 133, in _call
    raise ValueError('Request was unsuccessful {} time(s)'
ValueError: Request was unsuccessful 6 time(s)
Unhandled exception on store_message
Traceback (most recent call last):
  File "/usr/local/lib/python3.10/dist-packages/telethon/client/updates.py", line 570, in _dispatch_update
    await callback(event)
  File "/root/bot/bot.py", line 43, in store_message
    await client.send_message(event.chat_id, message)  # Отправляем сообщение в беседу
  File "/usr/local/lib/python3.10/dist-packages/telethon/client/messages.py", line 905, in send_message
    result = await self(request)
  File "/usr/local/lib/python3.10/dist-packages/telethon/client/users.py", line 30, in __call__
    return await self._call(self._sender, request, ordered=ordered)
  File "/usr/local/lib/python3.10/dist-packages/telethon/client/users.py", line 133, in _call
    raise ValueError('Request was unsuccessful {} time(s)'
ValueError: Request was unsuccessful 6 time(s)
Unhandled exception on store_message
Traceback (most recent call last):
  File "/usr/local/lib/python3.10/dist-packages/telethon/client/updates.py", line 570, in _dispatch_update
    await callback(event)
  File "/root/bot/bot.py", line 43, in store_message
    await client.send_message(event.chat_id, message)  # Отправляем сообщение в беседу
  File "/usr/local/lib/python3.10/dist-packages/telethon/client/messages.py", line 905, in send_message
    result = await self(request)
  File "/usr/local/lib/python3.10/dist-packages/telethon/client/users.py", line 30, in __call__
    return await self._call(self._sender, request, ordered=ordered)
  File "/usr/local/lib/python3.10/dist-packages/telethon/client/users.py", line 133, in _call
    raise ValueError('Request was unsuccessful {} time(s)'
ValueError: Request was unsuccessful 6 time(s)
Unhandled exception on store_message
Traceback (most recent call last):
  File "/usr/local/lib/python3.10/dist-packages/telethon/client/updates.py", line 570, in _dispatch_update
    await callback(event)
  File "/root/bot/bot.py", line 43, in store_message
    await client.send_message(event.chat_id, message)  # Отправляем сообщение в беседу
  File "/usr/local/lib/python3.10/dist-packages/telethon/client/messages.py", line 905, in send_message
    result = await self(request)
  File "/usr/local/lib/python3.10/dist-packages/telethon/client/users.py", line 30, in __call__
    return await self._call(self._sender, request, ordered=ordered)
  File "/usr/local/lib/python3.10/dist-packages/telethon/client/users.py", line 133, in _call
    raise ValueError('Request was unsuccessful {} time(s)'
ValueError: Request was unsuccessful 6 time(s)
Unhandled exception on store_message
Traceback (most recent call last):
  File "/usr/local/lib/python3.10/dist-packages/telethon/client/updates.py", line 570, in _dispatch_update
    await callback(event)
  File "/root/bot/bot.py", line 43, in store_message
    await client.send_message(event.chat_id, message)  # Отправляем сообщение в беседу
  File "/usr/local/lib/python3.10/dist-packages/telethon/client/messages.py", line 905, in send_message
    result = await self(request)
  File "/usr/local/lib/python3.10/dist-packages/telethon/client/users.py", line 30, in __call__
    return await self._call(self._sender, request, ordered=ordered)
  File "/usr/local/lib/python3.10/dist-packages/telethon/client/users.py", line 133, in _call
    raise ValueError('Request was unsuccessful {} time(s)'
ValueError: Request was unsuccessful 6 time(s)
Unhandled exception on store_message
Traceback (most recent call last):
  File "/usr/local/lib/python3.10/dist-packages/telethon/client/updates.py", line 570, in _dispatch_update
    await callback(event)
  File "/root/bot/bot.py", line 43, in store_message
    await client.send_message(event.chat_id, message)  # Отправляем сообщение в беседу
  File "/usr/local/lib/python3.10/dist-packages/telethon/client/messages.py", line 905, in send_message
    result = await self(request)
  File "/usr/local/lib/python3.10/dist-packages/telethon/client/users.py", line 30, in __call__
    return await self._call(self._sender, request, ordered=ordered)
  File "/usr/local/lib/python3.10/dist-packages/telethon/client/users.py", line 133, in _call
    raise ValueError('Request was unsuccessful {} time(s)'
ValueError: Request was unsuccessful 6 time(s)
Unhandled exception on store_message
Traceback (most recent call last):
  File "/usr/local/lib/python3.10/dist-packages/telethon/client/updates.py", line 570, in _dispatch_update
    await callback(event)
  File "/root/bot/bot.py", line 43, in store_message
    await client.send_message(event.chat_id, message)  # Отправляем сообщение в беседу
  File "/usr/local/lib/python3.10/dist-packages/telethon/client/messages.py", line 905, in send_message
    result = await self(request)
  File "/usr/local/lib/python3.10/dist-packages/telethon/client/users.py", line 30, in __call__
    return await self._call(self._sender, request, ordered=ordered)
  File "/usr/local/lib/python3.10/dist-packages/telethon/client/users.py", line 133, in _call
    raise ValueError('Request was unsuccessful {} time(s)'
ValueError: Request was unsuccessful 6 time(s)
Unhandled exception on store_message
Traceback (most recent call last):
  File "/usr/local/lib/python3.10/dist-packages/telethon/client/updates.py", line 570, in _dispatch_update
    await callback(event)
  File "/root/bot/bot.py", line 43, in store_message
    await client.send_message(event.chat_id, message)  # Отправляем сообщение в беседу
  File "/usr/local/lib/python3.10/dist-packages/telethon/client/messages.py", line 905, in send_message
    result = await self(request)
  File "/usr/local/lib/python3.10/dist-packages/telethon/client/users.py", line 30, in __call__
    return await self._call(self._sender, request, ordered=ordered)
  File "/usr/local/lib/python3.10/dist-packages/telethon/client/users.py", line 133, in _call
    raise ValueError('Request was unsuccessful {} time(s)'
ValueError: Request was unsuccessful 6 time(s)
Unhandled exception on store_message
Traceback (most recent call last):
  File "/usr/local/lib/python3.10/dist-packages/telethon/client/updates.py", line 570, in _dispatch_update
    await callback(event)
  File "/root/bot/bot.py", line 43, in store_message
    await client.send_message(event.chat_id, message)  # Отправляем сообщение в беседу
  File "/usr/local/lib/python3.10/dist-packages/telethon/client/messages.py", line 905, in send_message
    result = await self(request)
  File "/usr/local/lib/python3.10/dist-packages/telethon/client/users.py", line 30, in __call__
    return await self._call(self._sender, request, ordered=ordered)
  File "/usr/local/lib/python3.10/dist-packages/telethon/client/users.py", line 133, in _call
    raise ValueError('Request was unsuccessful {} time(s)'
ValueError: Request was unsuccessful 6 time(s)
Unhandled exception on store_message
Traceback (most recent call last):
  File "/usr/local/lib/python3.10/dist-packages/telethon/client/updates.py", line 570, in _dispatch_update
    await callback(event)
  File "/root/bot/bot.py", line 43, in store_message
    await client.send_message(event.chat_id, message)  # Отправляем сообщение в беседу
  File "/usr/local/lib/python3.10/dist-packages/telethon/client/messages.py", line 905, in send_message
    result = await self(request)
  File "/usr/local/lib/python3.10/dist-packages/telethon/client/users.py", line 30, in __call__
    return await self._call(self._sender, request, ordered=ordered)
  File "/usr/local/lib/python3.10/dist-packages/telethon/client/users.py", line 133, in _call
    raise ValueError('Request was unsuccessful {} time(s)'
ValueError: Request was unsuccessful 6 time(s)
Unhandled exception on store_message
Traceback (most recent call last):
  File "/usr/local/lib/python3.10/dist-packages/telethon/client/updates.py", line 570, in _dispatch_update
    await callback(event)
  File "/root/bot/bot.py", line 43, in store_message
    await client.send_message(event.chat_id, message)  # Отправляем сообщение в беседу
  File "/usr/local/lib/python3.10/dist-packages/telethon/client/messages.py", line 905, in send_message
    result = await self(request)
  File "/usr/local/lib/python3.10/dist-packages/telethon/client/users.py", line 30, in __call__
    return await self._call(self._sender, request, ordered=ordered)
  File "/usr/local/lib/python3.10/dist-packages/telethon/client/users.py", line 133, in _call
    raise ValueError('Request was unsuccessful {} time(s)'
ValueError: Request was unsuccessful 6 time(s)
Unhandled exception on store_message
Traceback (most recent call last):
  File "/usr/local/lib/python3.10/dist-packages/telethon/client/updates.py", line 570, in _dispatch_update
    await callback(event)
  File "/root/bot/bot.py", line 43, in store_message
    await client.send_message(event.chat_id, message)  # Отправляем сообщение в беседу
  File "/usr/local/lib/python3.10/dist-packages/telethon/client/messages.py", line 905, in send_message
    result = await self(request)
  File "/usr/local/lib/python3.10/dist-packages/telethon/client/users.py", line 30, in __call__
    return await self._call(self._sender, request, ordered=ordered)
  File "/usr/local/lib/python3.10/dist-packages/telethon/client/users.py", line 133, in _call
    raise ValueError('Request was unsuccessful {} time(s)'
ValueError: Request was unsuccessful 6 time(s)
Unhandled exception on store_message
Traceback (most recent call last):
  File "/usr/local/lib/python3.10/dist-packages/telethon/client/updates.py", line 570, in _dispatch_update
    await callback(event)
  File "/root/bot/bot.py", line 43, in store_message
    await client.send_message(event.chat_id, message)  # Отправляем сообщение в беседу
  File "/usr/local/lib/python3.10/dist-packages/telethon/client/messages.py", line 905, in send_message
    result = await self(request)
  File "/usr/local/lib/python3.10/dist-packages/telethon/client/users.py", line 30, in __call__
    return await self._call(self._sender, request, ordered=ordered)
  File "/usr/local/lib/python3.10/dist-packages/telethon/client/users.py", line 133, in _call
    raise ValueError('Request was unsuccessful {} time(s)'
ValueError: Request was unsuccessful 6 time(s)
Unhandled exception on store_message
Traceback (most recent call last):
  File "/usr/local/lib/python3.10/dist-packages/telethon/client/updates.py", line 570, in _dispatch_update
    await callback(event)
  File "/root/bot/bot.py", line 43, in store_message
    await client.send_message(event.chat_id, message)  # Отправляем сообщение в беседу
  File "/usr/local/lib/python3.10/dist-packages/telethon/client/messages.py", line 905, in send_message
    result = await self(request)
  File "/usr/local/lib/python3.10/dist-packages/telethon/client/users.py", line 30, in __call__
    return await self._call(self._sender, request, ordered=ordered)
  File "/usr/local/lib/python3.10/dist-packages/telethon/client/users.py", line 133, in _call
    raise ValueError('Request was unsuccessful {} time(s)'
ValueError: Request was unsuccessful 6 time(s)
Unhandled exception on store_message
Traceback (most recent call last):
  File "/usr/local/lib/python3.10/dist-packages/telethon/client/updates.py", line 570, in _dispatch_update
    await callback(event)
  File "/root/bot/bot.py", line 43, in store_message
    await client.send_message(event.chat_id, message)  # Отправляем сообщение в беседу
  File "/usr/local/lib/python3.10/dist-packages/telethon/client/messages.py", line 905, in send_message
    result = await self(request)
  File "/usr/local/lib/python3.10/dist-packages/telethon/client/users.py", line 30, in __call__
    return await self._call(self._sender, request, ordered=ordered)
  File "/usr/local/lib/python3.10/dist-packages/telethon/client/users.py", line 133, in _call
    raise ValueError('Request was unsuccessful {} time(s)'
ValueError: Request was unsuccessful 6 time(s)
Unhandled exception on store_message
Traceback (most recent call last):
  File "/usr/local/lib/python3.10/dist-packages/telethon/client/updates.py", line 570, in _dispatch_update
    await callback(event)
  File "/root/bot/bot.py", line 43, in store_message
    await client.send_message(event.chat_id, message)  # Отправляем сообщение в беседу
  File "/usr/local/lib/python3.10/dist-packages/telethon/client/messages.py", line 905, in send_message
    result = await self(request)
  File "/usr/local/lib/python3.10/dist-packages/telethon/client/users.py", line 30, in __call__
    return await self._call(self._sender, request, ordered=ordered)
  File "/usr/local/lib/python3.10/dist-packages/telethon/client/users.py", line 133, in _call
    raise ValueError('Request was unsuccessful {} time(s)'
ValueError: Request was unsuccessful 6 time(s)
Server closed the connection: 0 bytes read on a total of 8 expected bytes
Error executing high-level request after reconnect: <class 'sqlite3.OperationalError'>: attempt to write a readonly database
Server closed the connection: 0 bytes read on a total of 8 expected bytes
Error executing high-level request after reconnect: <class 'sqlite3.OperationalError'>: attempt to write a readonly database
Server closed the connection: 0 bytes read on a total of 8 expected bytes
Error executing high-level request after reconnect: <class 'sqlite3.OperationalError'>: attempt to write a readonly database
Cannot get difference since the account is likely misusing the session: attempt to write a readonly database
Unhandled exception from keepalive_handle after cancelling <class '_asyncio.Task'> (<Task finished name='Task-8' coro=<UpdateMethods._keepalive_loop() done, defined at /usr/local/lib/python3.10/dist-packages/telethon/client/updates.py:481> exception=OperationalError('attempt to write a readonly database')>)
Traceback (most recent call last):
  File "/usr/local/lib/python3.10/dist-packages/telethon/helpers.py", line 176, in _cancel
    await task
  File "/usr/local/lib/python3.10/dist-packages/telethon/client/updates.py", line 517, in _keepalive_loop
    self._save_states_and_entities()
  File "/usr/local/lib/python3.10/dist-packages/telethon/client/telegrambaseclient.py", line 692, in _save_states_and_entities
    self.session.process_entities(types.contacts.ResolvedPeer(None, [e._as_input_peer() for e in entities], []))
  File "/usr/local/lib/python3.10/dist-packages/telethon/sessions/sqlite.py", line 301, in process_entities
    c.executemany(
sqlite3.OperationalError: attempt to write a readonly database
Task exception was never retrieved
future: <Task finished name='Task-1051' coro=<TelegramBaseClient._disconnect_coro() done, defined at /usr/local/lib/python3.10/dist-packages/telethon/client/telegrambaseclient.py:705> exception=OperationalError('attempt to write a readonly database')>
Traceback (most recent call last):
  File "/usr/local/lib/python3.10/dist-packages/telethon/client/telegrambaseclient.py", line 735, in _disconnect_coro
    self._save_states_and_entities()
  File "/usr/local/lib/python3.10/dist-packages/telethon/client/telegrambaseclient.py", line 692, in _save_states_and_entities
    self.session.process_entities(types.contacts.ResolvedPeer(None, [e._as_input_peer() for e in entities], []))
  File "/usr/local/lib/python3.10/dist-packages/telethon/sessions/sqlite.py", line 301, in process_entities
    c.executemany(
sqlite3.OperationalError: attempt to write a readonly database
Unhandled exception from keepalive_handle after cancelling <class '_asyncio.Task'> (<Task finished name='Task-8' coro=<UpdateMethods._keepalive_loop() done, defined at /usr/local/lib/python3.10/dist-packages/telethon/client/updates.py:481> exception=OperationalError('attempt to write a readonly database')>)
Traceback (most recent call last):
  File "/usr/local/lib/python3.10/dist-packages/telethon/helpers.py", line 176, in _cancel
    await task
sqlite3.OperationalError: attempt to write a readonly database
Unhandled exception from keepalive_handle after cancelling <class '_asyncio.Task'> (<Task finished name='Task-8' coro=<UpdateMethods._keepalive_loop() done, defined at /usr/local/lib/python3.10/dist-packages/telethon/client/updates.py:481> exception=OperationalError('attempt to write a readonly database')>)
Traceback (most recent call last):
  File "/usr/local/lib/python3.10/dist-packages/telethon/client/updates.py", line 38, in _run_until_disconnected
    raise self._updates_error
  File "/usr/local/lib/python3.10/dist-packages/telethon/client/updates.py", line 308, in _update_loop
    diff = await self(get_diff)
  File "/usr/local/lib/python3.10/dist-packages/telethon/client/users.py", line 30, in __call__
    return await self._call(self._sender, request, ordered=ordered)
  File "/usr/local/lib/python3.10/dist-packages/telethon/client/users.py", line 88, in _call
    self.session.process_entities(result)
  File "/usr/local/lib/python3.10/dist-packages/telethon/sessions/sqlite.py", line 301, in process_entities
    c.executemany(
sqlite3.OperationalError: attempt to write a readonly database

During handling of the above exception, another exception occurred:

Traceback (most recent call last):
  File "/usr/local/lib/python3.10/dist-packages/telethon/client/updates.py", line 96, in run_until_disconnected
    return self.loop.run_until_complete(self._run_until_disconnected())
  File "/usr/lib/python3.10/asyncio/base_events.py", line 649, in run_until_complete
    return future.result()
  File "/usr/local/lib/python3.10/dist-packages/telethon/client/updates.py", line 43, in _run_until_disconnected
    await self.disconnect()
  File "/usr/local/lib/python3.10/dist-packages/telethon/client/telegrambaseclient.py", line 735, in _disconnect_coro
    self._save_states_and_entities()
  File "/usr/local/lib/python3.10/dist-packages/telethon/client/telegrambaseclient.py", line 692, in _save_states_and_entities
    self.session.process_entities(types.contacts.ResolvedPeer(None, [e._as_input_peer() for e in entities], []))
  File "/usr/local/lib/python3.10/dist-packages/telethon/sessions/sqlite.py", line 301, in process_entities
    c.executemany(
sqlite3.OperationalError: attempt to write a readonly database

During handling of the above exception, another exception occurred:

Traceback (most recent call last):
  File "/usr/local/lib/python3.10/dist-packages/telethon/helpers.py", line 176, in _cancel
    await task
sqlite3.OperationalError: attempt to write a readonly database
Traceback (most recent call last):
  File "/usr/local/lib/python3.10/dist-packages/telethon/client/updates.py", line 38, in _run_until_disconnected
    raise self._updates_error
  File "/usr/local/lib/python3.10/dist-packages/telethon/client/updates.py", line 308, in _update_loop
    diff = await self(get_diff)
  File "/usr/local/lib/python3.10/dist-packages/telethon/client/users.py", line 30, in __call__
    return await self._call(self._sender, request, ordered=ordered)
  File "/usr/local/lib/python3.10/dist-packages/telethon/client/users.py", line 88, in _call
    self.session.process_entities(result)
  File "/usr/local/lib/python3.10/dist-packages/telethon/sessions/sqlite.py", line 301, in process_entities
    c.executemany(
sqlite3.OperationalError: attempt to write a readonly database

During handling of the above exception, another exception occurred:

Traceback (most recent call last):
  File "/usr/local/lib/python3.10/dist-packages/telethon/client/updates.py", line 96, in run_until_disconnected
    return self.loop.run_until_complete(self._run_until_disconnected())
  File "/usr/lib/python3.10/asyncio/base_events.py", line 649, in run_until_complete
    return future.result()
  File "/usr/local/lib/python3.10/dist-packages/telethon/client/updates.py", line 43, in _run_until_disconnected
    await self.disconnect()
  File "/usr/local/lib/python3.10/dist-packages/telethon/client/telegrambaseclient.py", line 735, in _disconnect_coro
    self._save_states_and_entities()
  File "/usr/local/lib/python3.10/dist-packages/telethon/client/telegrambaseclient.py", line 692, in _save_states_and_entities
    self.session.process_entities(types.contacts.ResolvedPeer(None, [e._as_input_peer() for e in entities], []))
  File "/usr/local/lib/python3.10/dist-packages/telethon/sessions/sqlite.py", line 301, in process_entities
    c.executemany(
sqlite3.OperationalError: attempt to write a readonly database

During handling of the above exception, another exception occurred:

Traceback (most recent call last):
  File "/root/bot/bot.py", line 177, in <module>
    client.run_until_disconnected()
  File "/usr/local/lib/python3.10/dist-packages/telethon/client/updates.py", line 101, in run_until_disconnected
    self.disconnect()
  File "/usr/local/lib/python3.10/dist-packages/telethon/client/telegrambaseclient.py", line 649, in disconnect
    self.loop.run_until_complete(self._disconnect_coro())
  File "/usr/lib/python3.10/asyncio/base_events.py", line 649, in run_until_complete
    return future.result()
  File "/usr/local/lib/python3.10/dist-packages/telethon/client/telegrambaseclient.py", line 735, in _disconnect_coro
    self._save_states_and_entities()
  File "/usr/local/lib/python3.10/dist-packages/telethon/client/telegrambaseclient.py", line 692, in _save_states_and_entities
    self.session.process_entities(types.contacts.ResolvedPeer(None, [e._as_input_peer() for e in entities], []))
  File "/usr/local/lib/python3.10/dist-packages/telethon/sessions/sqlite.py", line 301, in process_entities
    c.executemany(
sqlite3.OperationalError: attempt to write a readonly database
Server closed the connection: [Errno 104] Connection reset by peer
Server closed the connection: [Errno 104] Connection reset by peer
